<?xml version="1.0"?>


<robot name="manipulator">
  
  <!-- ***** ABB-IRB120 ROBOT .urdf SERIAL CHAIN ***** -->

  <!-- Link list: -->
  <!-- base_link -->
  <link name="${prefix}base_link">
    <inertial>
      <mass value="6.215"/>
      <origin xyz="-0.04204 8.01E-05 0.07964" rpy="0 0 0"/>
      <inertia ixx="0.0247272" ixy="-8.0784E-05" ixz="0.00130902" iyy="0.0491285" iyz="-8.0419E-06" izz="0.0472376"/>
    </inertial>
    <visual>
      <origin xyz="0 0 0" rpy="0 0 0"/>
      <geometry>
        <mesh filename="file://$(find skywalker)/meshes/visual/base_link.dae"/>
      </geometry>
      <xacro:material_abb_orange />
    </visual>
    <collision>
      <origin xyz="0 0 0" rpy="0 0 0"/>
      <geometry>
        <mesh filename="file://$(find skywalker)/meshes/collision/base_link.stl"/>
      </geometry>
      <xacro:material_abb_yellow />
    </collision>
  </link>

  <!-- link_1 -->
  <link name="${prefix}link_1">
    <visual>
      <origin xyz="0 0 0" rpy="0 0 0"/>
      <geometry>
        <mesh filename="file://$(find skywalker)/meshes/visual/link_1.dae"/>
      </geometry>
      <xacro:material_abb_orange />
    </visual>
    <collision>
      <origin xyz="0 0 0" rpy="0 0 0"/>
      <geometry>
        <mesh filename="file://$(find skywalker)/meshes/collision/link_1.stl"/>
      </geometry>
      <xacro:material_abb_yellow />
    </collision>
  </link>

  <!-- link_2 -->
  <link name="${prefix}link_2">
    <visual>
      <origin xyz="0 0 0" rpy="0 0 0"/>
      <geometry>
        <mesh filename="file://$(find skywalker)/meshes/visual/link_2.dae"/>
      </geometry>
      <xacro:material_abb_orange />
    </visual>
    <collision>
      <origin xyz="0 0 0" rpy="0 0 0"/>
      <geometry>
        <mesh filename="file://$(find skywalker)/meshes/collision/link_2.stl"/>
      </geometry>
      <xacro:material_abb_yellow />
    </collision>
  </link>

  <!-- link_3 -->
  <link name="${prefix}link_3">
    <visual>
      <origin xyz="0 0 0" rpy="0 0 0"/>
      <geometry>
        <mesh filename="file://$(find skywalker)/meshes/visual/link_3.dae"/>
      </geometry>
      <xacro:material_abb_orange />
    </visual>
    <collision>
      <origin xyz="0 0 0" rpy="0 0 0"/>
      <geometry>
        <mesh filename="file://$(find skywalker)/meshes/collision/link_3.stl"/>
      </geometry>
      <xacro:material_abb_yellow />
    </collision>
  </link>

  <!-- link_4 -->
  <link name="${prefix}link_4">
    <visual>
      <origin xyz="0 0 0" rpy="0 0 0"/>
      <geometry>
        <mesh filename="file://$(find skywalker)/meshes/visual/link_4.dae"/>
      </geometry>
      <xacro:material_abb_orange />
    </visual>
    <collision>
      <origin xyz="0 0 0" rpy="0 0 0"/>
      <geometry>
        <mesh filename="file://$(find skywalker)/meshes/collision/link_4.stl"/>
      </geometry>
      <xacro:material_abb_yellow />
    </collision>
  </link>

  <!-- link_5 -->
  <link name="${prefix}link_5">
    <visual>
      <origin xyz="0 0 0" rpy="0 0 0"/>
      <geometry>
        <mesh filename="file://$(find skywalker)/meshes/visual/link_5.dae"/>
      </geometry>
      <xacro:material_abb_orange />
    </visual>
    <collision>
      <origin xyz="0 0 0" rpy="0 0 0"/>
      <geometry>
        <mesh filename="file://$(find skywalker)/meshes/collision/link_5.stl"/>
      </geometry>
      <xacro:material_abb_yellow />
    </collision>
  </link>

  <!-- link_6 -->
  <link name="${prefix}link_6">
    <visual>
      <origin xyz="0 0 0" rpy="0 0 0"/>
      <geometry>
        <mesh filename="file://$(find skywalker)/meshes/visual/link_6.dae"/>
      </geometry>
      <xacro:material_abb_black />
    </visual>
    <collision>
      <origin xyz="0 0 0" rpy="0 0 0"/>
      <geometry>
        <mesh filename="file://$(find skywalker)/meshes/collision/link_6.stl"/>
      </geometry>
      <xacro:material_abb_yellow />
    </collision>
  </link>
  <!-- end of link list -->

  <!-- Joint list: -->
  <!-- joint_1 -->
  <joint name="${prefix}irb120_joint1" type="revolute">
    <origin rpy="0 0 0" xyz="0 0 0"/>
    <parent link="${prefix}base_link"/>
    <child link="${prefix}link_1"/>
    <limit effort="0" lower="-2.87979" upper="2.87979" velocity="4.36332"/>
    <axis xyz="0 0 1"/>
    <dynamics damping="50.0" friction="1.0"/>
  </joint>

  <!-- joint_2 -->
  <joint name="${prefix}irb120_joint2" type="revolute">
    <origin rpy="0 0 0" xyz="0 0 0.29"/>
    <parent link="${prefix}link_1"/>
    <child link="${prefix}link_2"/>
    <limit effort="0" lower="-1.91986" upper="1.91986" velocity="4.36332"/>
    <axis xyz="0 1 0"/>
    <dynamics damping="50.0" friction="1.0"/>
  </joint>

  <!-- joint_3 -->
  <joint name="${prefix}irb120_joint3" type="revolute">
    <origin rpy="0 0 0" xyz="0 0 0.27"/>
    <parent link="${prefix}link_2"/>
    <child link="${prefix}link_3"/>
    <limit effort="0" lower="-1.91986" upper="1.22173" velocity="4.36332"/>
    <axis xyz="0 1 0"/>
    <dynamics damping="10.0" friction="1.0"/>
  </joint>

  <!-- joint_4 -->
  <joint name="${prefix}irb120_joint4" type="revolute">
    <origin rpy="0 0 0" xyz="0 0 0.07"/>
    <parent link="${prefix}link_3"/>
    <child link="${prefix}link_4"/>
    <limit effort="0" lower="-2.79253" upper="2.79253" velocity="5.58505"/>
    <axis xyz="1 0 0"/>
    <dynamics damping="5.0" friction="1.0"/>
  </joint>

  <!-- joint_5 -->
  <joint name="${prefix}irb120_joint5" type="revolute">
    <origin rpy="0 0 0" xyz="0.302 0 0"/>
    <parent link="${prefix}link_4"/>
    <child link="${prefix}link_5"/>
    <limit effort="0" lower="-2.094395" upper="2.094395" velocity="5.58505"/>
    <axis xyz="0 1 0"/>
    <dynamics damping="2.0" friction="1.0"/>
  </joint>

  <!-- joint_6 -->
  <joint name="${prefix}irb120_joint6" type="revolute">
    <origin rpy="0 0 0" xyz="0.072 0 0"/>
    <parent link="${prefix}link_5"/>
    <child link="${prefix}link_6"/>
    <limit effort="0" lower="-6.98132" upper="6.98132" velocity="7.33038"/>
    <axis xyz="1 0 0"/>
    <dynamics damping="1.0" friction="1.0"/>
  </joint>
  <!-- end of joint list -->

  <!-- ROS-Industrial 'base' frame: base_link to ABB World Coordinates transform -->
  <link name="${prefix}base" />
  <joint name="${prefix}base_link-base" type="fixed">
    <origin xyz="0 0 0" rpy="0 0 0"/>
    <parent link="${prefix}base_link"/>
    <child link="${prefix}base"/>
  </joint>

  <!-- ROS-Industrial 'flange' frame: attachment point for EEF models -->
  <link name="${prefix}flange"/>
  <joint type="fixed" name="${prefix}joint_6-flange">
    <origin xyz="0 0 0" rpy="0 0 0"/>
    <parent link="${prefix}link_6"/>
    <child link="${prefix}flange"/>
  </joint>

  <!-- ROS-Industrial 'tool0' frame: all-zeros tool frame -->
  <link name="${prefix}tool0" />
  <joint name="${prefix}link_6-tool0" type="fixed">
    <origin xyz="0 0 0" rpy="0 ${radians(90)} 0" />
    <parent link="${prefix}flange" />
    <child link="${prefix}tool0" />
  </joint>
    
</robot>
