<sdf version='1.7'>
  <model name='mobile_manipulator'>
    <link name='mobile_base_link'>
      <inertial>
        <pose>-3e-05 -0.015538 0.157015 1.5708 -0 1.5708</pose>
        <mass>16.815</mass>
        <inertia>
          <ixx>0.856913</ixx>
          <ixy>0.07254</ixy>
          <ixz>6.75909e-05</ixz>
          <iyy>0.218838</iyy>
          <iyz>0.00014376</iyz>
          <izz>0.874738</izz>
        </inertia>
      </inertial>
      <collision name='mobile_base_link_collision'>
        <pose>0 0 0 0 -0 0</pose>
        <geometry>
          <box>
            <size>0.3 0.3 0.1</size>
          </box>
        </geometry>
        <surface>
          <contact>
            <ode/>
          </contact>
          <friction>
            <ode/>
          </friction>
        </surface>
      </collision>
      <collision name='mobile_base_link_fixed_joint_lump__box_link_collision_1'>
        <pose>0 0 0.2 0 -0 0</pose>
        <geometry>
          <box>
            <size>0.3 0.3 0.3</size>
          </box>
        </geometry>
        <surface>
          <contact>
            <ode/>
          </contact>
          <friction>
            <ode/>
          </friction>
        </surface>
      </collision>
      <collision name='mobile_base_link_fixed_joint_lump__base_link_collision_2'>
        <pose>0 0 0.35 0 -0 1.5708</pose>
        <geometry>
          <mesh>
            <scale>1 1 1</scale>
            <uri>file:///home/dushyant/Documents/IRB_Mobile/MobileRobot/install/robotbody/share/robotbody/meshes/collision/base_link.stl</uri>
          </mesh>
        </geometry>
      </collision>
      <collision name='mobile_base_link_fixed_joint_lump__back_caster_collision_3'>
        <pose>-0.15 0 -0.05 0 -0 0</pose>
        <geometry>
          <sphere>
            <radius>0.07</radius>
          </sphere>
        </geometry>
        <surface>
          <contact>
            <ode>
              <kp>1e+07</kp>
              <kd>1</kd>
            </ode>
          </contact>
          <friction>
            <ode>
              <mu>0.01</mu>
              <mu2>0.01</mu2>
            </ode>
          </friction>
        </surface>
      </collision>
      <collision name='mobile_base_link_fixed_joint_lump__front_caster_collision_4'>
        <pose>0.15 0 -0.05 0 -0 0</pose>
        <geometry>
          <sphere>
            <radius>0.07</radius>
          </sphere>
        </geometry>
        <surface>
          <contact>
            <ode>
              <kp>1e+07</kp>
              <kd>1</kd>
            </ode>
          </contact>
          <friction>
            <ode>
              <mu>0.01</mu>
              <mu2>0.01</mu2>
            </ode>
          </friction>
        </surface>
      </collision>
      <visual name='mobile_base_link_visual'>
        <pose>0 0 0 0 -0 0</pose>
        <geometry>
          <box>
            <size>0.3 0.3 0.1</size>
          </box>
        </geometry>
        <material>
          <script>
            <name>Gazebo/Pioneer2Body</name>
            <uri>file://media/materials/scripts/gazebo.material</uri>
          </script>
        </material>
      </visual>
      <visual name='mobile_base_link_fixed_joint_lump__box_link_visual_1'>
        <pose>0 0 0.2 0 -0 0</pose>
        <geometry>
          <box>
            <size>0.3 0.3 0.3</size>
          </box>
        </geometry>
        <material>
          <script>
            <name>Gazebo/Pioneer2Body</name>
            <uri>file://media/materials/scripts/gazebo.material</uri>
          </script>
        </material>
      </visual>
      <visual name='mobile_base_link_fixed_joint_lump__base_link_visual_2'>
        <pose>0 0 0.35 0 -0 1.5708</pose>
        <geometry>
          <mesh>
            <scale>1 1 1</scale>
            <uri>file:///home/dushyant/Documents/IRB_Mobile/MobileRobot/install/robotbody/share/robotbody/meshes/visual/base_link.dae</uri>
          </mesh>
        </geometry>
      </visual>
    </link>
    <joint name='irb120_joint1' type='revolute'>
      <pose relative_to='mobile_base_link'>0 0 0.35 0 -0 1.5708</pose>
      <parent>mobile_base_link</parent>
      <child>link_1</child>
      <axis>
        <xyz>0 0 1</xyz>
        <limit>
          <lower>-2.87979</lower>
          <upper>2.87979</upper>
          <effort>0</effort>
          <velocity>4.36332</velocity>
        </limit>
        <dynamics>
          <damping>50</damping>
          <friction>1</friction>
          <spring_reference>0</spring_reference>
          <spring_stiffness>0</spring_stiffness>
        </dynamics>
      </axis>
    </joint>
    <link name='link_1'>
      <pose relative_to='irb120_joint1'>0 0 0 0 -0 0</pose>
      <inertial>
        <pose>9.8e-05 -0.00012 0.23841 0 -0 0</pose>
        <mass>3.067</mass>
        <inertia>
          <ixx>0.0142175</ixx>
          <ixy>-1.28579e-05</ixy>
          <ixz>-2.31364e-05</ixz>
          <iyy>0.0144041</iyy>
          <iyz>1.93404e-05</iyz>
          <izz>0.0104533</izz>
        </inertia>
      </inertial>
      <collision name='link_1_collision'>
        <pose>0 0 0 0 -0 0</pose>
        <geometry>
          <mesh>
            <scale>1 1 1</scale>
            <uri>file:///home/dushyant/Documents/IRB_Mobile/MobileRobot/install/robotbody/share/robotbody/meshes/collision/link_1.stl</uri>
          </mesh>
        </geometry>
      </collision>
      <visual name='link_1_visual'>
        <pose>0 0 0 0 -0 0</pose>
        <geometry>
          <mesh>
            <scale>1 1 1</scale>
            <uri>file:///home/dushyant/Documents/IRB_Mobile/MobileRobot/install/robotbody/share/robotbody/meshes/visual/link_1.dae</uri>
          </mesh>
        </geometry>
      </visual>
    </link>
    <joint name='irb120_joint2' type='revolute'>
      <pose relative_to='link_1'>0 0 0.29 0 -0 0</pose>
      <parent>link_1</parent>
      <child>link_2</child>
      <axis>
        <xyz>0 1 0</xyz>
        <limit>
          <lower>-1.91986</lower>
          <upper>1.91986</upper>
          <effort>0</effort>
          <velocity>4.36332</velocity>
        </limit>
        <dynamics>
          <damping>50</damping>
          <friction>1</friction>
          <spring_reference>0</spring_reference>
          <spring_stiffness>0</spring_stiffness>
        </dynamics>
      </axis>
    </joint>
    <link name='link_2'>
      <pose relative_to='irb120_joint2'>0 0 0 0 -0 0</pose>
      <inertial>
        <pose>0.00078 -0.00212 0.10124 0 -0 0</pose>
        <mass>3.909</mass>
        <inertia>
          <ixx>0.0603111</ixx>
          <ixy>9.83431e-06</ixy>
          <ixz>5.72407e-05</ixz>
          <iyy>0.041569</iyy>
          <iyz>-0.00050497</iyz>
          <izz>0.0259548</izz>
        </inertia>
      </inertial>
      <collision name='link_2_collision'>
        <pose>0 0 0 0 -0 0</pose>
        <geometry>
          <mesh>
            <scale>1 1 1</scale>
            <uri>file:///home/dushyant/Documents/IRB_Mobile/MobileRobot/install/robotbody/share/robotbody/meshes/collision/link_2.stl</uri>
          </mesh>
        </geometry>
      </collision>
      <visual name='link_2_visual'>
        <pose>0 0 0 0 -0 0</pose>
        <geometry>
          <mesh>
            <scale>1 1 1</scale>
            <uri>file:///home/dushyant/Documents/IRB_Mobile/MobileRobot/install/robotbody/share/robotbody/meshes/visual/link_2.dae</uri>
          </mesh>
        </geometry>
      </visual>
    </link>
    <joint name='irb120_joint3' type='revolute'>
      <pose relative_to='link_2'>0 0 0.27 0 -0 0</pose>
      <parent>link_2</parent>
      <child>link_3</child>
      <axis>
        <xyz>0 1 0</xyz>
        <limit>
          <lower>-1.91986</lower>
          <upper>1.22173</upper>
          <effort>0</effort>
          <velocity>4.36332</velocity>
        </limit>
        <dynamics>
          <damping>10</damping>
          <friction>1</friction>
          <spring_reference>0</spring_reference>
          <spring_stiffness>0</spring_stiffness>
        </dynamics>
      </axis>
    </joint>
    <link name='link_3'>
      <pose relative_to='irb120_joint3'>0 0 0 0 -0 0</pose>
      <inertial>
        <pose>0.02281 0.00106 0.05791 0 -0 0</pose>
        <mass>2.944</mass>
        <inertia>
          <ixx>0.00835606</ixx>
          <ixy>-8.01545e-05</ixy>
          <ixz>0.00142884</ixz>
          <iyy>0.016713</iyy>
          <iyz>-0.000182227</iyz>
          <izz>0.0126984</izz>
        </inertia>
      </inertial>
      <collision name='link_3_collision'>
        <pose>0 0 0 0 -0 0</pose>
        <geometry>
          <mesh>
            <scale>1 1 1</scale>
            <uri>file:///home/dushyant/Documents/IRB_Mobile/MobileRobot/install/robotbody/share/robotbody/meshes/collision/link_3.stl</uri>
          </mesh>
        </geometry>
      </collision>
      <visual name='link_3_visual'>
        <pose>0 0 0 0 -0 0</pose>
        <geometry>
          <mesh>
            <scale>1 1 1</scale>
            <uri>file:///home/dushyant/Documents/IRB_Mobile/MobileRobot/install/robotbody/share/robotbody/meshes/visual/link_3.dae</uri>
          </mesh>
        </geometry>
      </visual>
    </link>
    <joint name='irb120_joint4' type='revolute'>
      <pose relative_to='link_3'>0 0 0.07 0 -0 0</pose>
      <parent>link_3</parent>
      <child>link_4</child>
      <axis>
        <xyz>1 0 0</xyz>
        <limit>
          <lower>-2.79253</lower>
          <upper>2.79253</upper>
          <effort>0</effort>
          <velocity>5.58505</velocity>
        </limit>
        <dynamics>
          <damping>5</damping>
          <friction>1</friction>
          <spring_reference>0</spring_reference>
          <spring_stiffness>0</spring_stiffness>
        </dynamics>
      </axis>
    </joint>
    <link name='link_4'>
      <pose relative_to='irb120_joint4'>0 0 0 0 -0 0</pose>
      <inertial>
        <pose>0.2247 0.00015 0.00041 0 -0 0</pose>
        <mass>1.328</mass>
        <inertia>
          <ixx>0.00284661</ixx>
          <ixy>-2.12765e-05</ixy>
          <ixz>-1.6435e-05</ixz>
          <iyy>0.00401346</iyy>
          <iyz>1.31336e-05</iyz>
          <izz>0.0052535</izz>
        </inertia>
      </inertial>
      <collision name='link_4_collision'>
        <pose>0 0 0 0 -0 0</pose>
        <geometry>
          <mesh>
            <scale>1 1 1</scale>
            <uri>file:///home/dushyant/Documents/IRB_Mobile/MobileRobot/install/robotbody/share/robotbody/meshes/collision/link_4.stl</uri>
          </mesh>
        </geometry>
      </collision>
      <visual name='link_4_visual'>
        <pose>0 0 0 0 -0 0</pose>
        <geometry>
          <mesh>
            <scale>1 1 1</scale>
            <uri>file:///home/dushyant/Documents/IRB_Mobile/MobileRobot/install/robotbody/share/robotbody/meshes/visual/link_4.dae</uri>
          </mesh>
        </geometry>
      </visual>
    </link>
    <joint name='irb120_joint5' type='revolute'>
      <pose relative_to='link_4'>0.302 0 0 0 -0 0</pose>
      <parent>link_4</parent>
      <child>link_5</child>
      <axis>
        <xyz>0 1 0</xyz>
        <limit>
          <lower>-2.0944</lower>
          <upper>2.0944</upper>
          <effort>0</effort>
          <velocity>5.58505</velocity>
        </limit>
        <dynamics>
          <damping>2</damping>
          <friction>1</friction>
          <spring_reference>0</spring_reference>
          <spring_stiffness>0</spring_stiffness>
        </dynamics>
      </axis>
    </joint>
    <link name='link_5'>
      <pose relative_to='irb120_joint5'>0 0 0 0 -0 0</pose>
      <inertial>
        <pose>-0.00109 3.7e-05 6.2e-05 0 -0 0</pose>
        <mass>0.546</mass>
        <inertia>
          <ixx>0.000404891</ixx>
          <ixy>1.61943e-06</ixy>
          <ixz>8.46805e-07</ixz>
          <iyy>0.000892825</iyy>
          <iyz>-1.51792e-08</iyz>
          <izz>0.000815468</izz>
        </inertia>
      </inertial>
      <collision name='link_5_collision'>
        <pose>0 0 0 0 -0 0</pose>
        <geometry>
          <mesh>
            <scale>1 1 1</scale>
            <uri>file:///home/dushyant/Documents/IRB_Mobile/MobileRobot/install/robotbody/share/robotbody/meshes/collision/link_5.stl</uri>
          </mesh>
        </geometry>
      </collision>
      <visual name='link_5_visual'>
        <pose>0 0 0 0 -0 0</pose>
        <geometry>
          <mesh>
            <scale>1 1 1</scale>
            <uri>file:///home/dushyant/Documents/IRB_Mobile/MobileRobot/install/robotbody/share/robotbody/meshes/visual/link_5.dae</uri>
          </mesh>
        </geometry>
      </visual>
    </link>
    <joint name='irb120_joint6' type='revolute'>
      <pose relative_to='link_5'>0.072 0 0 0 -0 0</pose>
      <parent>link_5</parent>
      <child>link_6</child>
      <axis>
        <xyz>1 0 0</xyz>
        <limit>
          <lower>-6.98132</lower>
          <upper>6.98132</upper>
          <effort>0</effort>
          <velocity>7.33038</velocity>
        </limit>
        <dynamics>
          <damping>1</damping>
          <friction>1</friction>
          <spring_reference>0</spring_reference>
          <spring_stiffness>0</spring_stiffness>
        </dynamics>
      </axis>
    </joint>
    <link name='link_6'>
      <pose relative_to='irb120_joint6'>0 0 0 0 -0 0</pose>
      <inertial>
        <pose>-0.006006 -0.001283 0.000632 0 -0 0</pose>
        <mass>0.143</mass>
        <inertia>
          <ixx>0.00300649</ixx>
          <ixy>4.3785e-06</ixy>
          <ixz>-2.48952e-06</ixz>
          <iyy>0.00300556</iyy>
          <iyz>2.78765e-06</iyz>
          <izz>0.00300888</izz>
        </inertia>
      </inertial>
      <collision name='link_6_collision'>
        <pose>0 0 0 0 -0 0</pose>
        <geometry>
          <mesh>
            <scale>1 1 1</scale>
            <uri>file:///home/dushyant/Documents/IRB_Mobile/MobileRobot/install/robotbody/share/robotbody/meshes/collision/link_6.stl</uri>
          </mesh>
        </geometry>
      </collision>
      <collision name='link_6_fixed_joint_lump__schunk_coupler_collision_1'>
        <pose>0.001 0 0 1.5708 0 1.5708</pose>
        <geometry>
          <mesh>
            <scale>1 1 1</scale>
            <uri>file:///home/dushyant/Documents/IRB_Mobile/MobileRobot/install/robotbody/share/robotbody/meshes/egp64/egp64_Adapter.dae</uri>
          </mesh>
        </geometry>
        <surface>
          <contact>
            <ode/>
          </contact>
          <friction>
            <ode>
              <mu>0.9</mu>
              <mu2>0.9</mu2>
            </ode>
          </friction>
        </surface>
      </collision>
      <collision name='link_6_fixed_joint_lump__egp64_gripper_base_link_collision_2'>
        <pose>0.02147 -0.03205 0.01812 1.5708 0 1.5708</pose>
        <geometry>
          <mesh>
            <scale>1 1 1</scale>
            <uri>file:///home/dushyant/Documents/IRB_Mobile/MobileRobot/install/robotbody/share/robotbody/meshes/egp64/egp64_BaseNoAdapter.dae</uri>
          </mesh>
        </geometry>
      </collision>
      <visual name='link_6_visual'>
        <pose>0 0 0 0 -0 0</pose>
        <geometry>
          <mesh>
            <scale>1 1 1</scale>
            <uri>file:///home/dushyant/Documents/IRB_Mobile/MobileRobot/install/robotbody/share/robotbody/meshes/visual/link_6.dae</uri>
          </mesh>
        </geometry>
      </visual>
      <visual name='link_6_fixed_joint_lump__schunk_coupler_visual_1'>
        <pose>0.001 0 0 1.5708 0 1.5708</pose>
        <geometry>
          <mesh>
            <scale>1 1 1</scale>
            <uri>file:///home/dushyant/Documents/IRB_Mobile/MobileRobot/install/robotbody/share/robotbody/meshes/egp64/egp64_Adapter.dae</uri>
          </mesh>
        </geometry>
        <material>
          <script>
            <name>Gazebo/Black</name>
            <uri>file://media/materials/scripts/gazebo.material</uri>
          </script>
        </material>
      </visual>
      <visual name='link_6_fixed_joint_lump__egp64_gripper_base_link_visual_2'>
        <pose>0.02147 -0.03205 0.01812 1.5708 0 1.5708</pose>
        <geometry>
          <mesh>
            <scale>1 1 1</scale>
            <uri>file:///home/dushyant/Documents/IRB_Mobile/MobileRobot/install/robotbody/share/robotbody/meshes/egp64/egp64_BaseNoAdapter.dae</uri>
          </mesh>
        </geometry>
      </visual>
    </link>
    <joint name='EE_egp64_joint' type='prismatic'>
      <pose relative_to='link_6'>0.17147 0.00095 0.00012 1.5708 0 1.5708</pose>
      <parent>link_6</parent>
      <child>EE_egp64</child>
      <axis>
        <xyz>1 0 0</xyz>
        <limit>
          <lower>0</lower>
          <upper>0</upper>
          <effort>10000</effort>
          <velocity>0</velocity>
        </limit>
        <dynamics>
          <damping>1</damping>
          <friction>1</friction>
          <spring_reference>0</spring_reference>
          <spring_stiffness>0</spring_stiffness>
        </dynamics>
      </axis>
    </joint>
    <link name='EE_egp64'>
      <pose relative_to='EE_egp64_joint'>0 0 0 0 -0 0</pose>
      <inertial>
        <pose>0 0 0 0 -0 0</pose>
        <mass>1e-05</mass>
        <inertia>
          <ixx>0.001</ixx>
          <ixy>0</ixy>
          <ixz>0</ixz>
          <iyy>0.001</iyy>
          <iyz>0</iyz>
          <izz>0.001</izz>
        </inertia>
      </inertial>
      <visual name='EE_egp64_visual'>
        <pose>0 0 0 0 -0 0</pose>
        <geometry>
          <box>
            <size>0.001 0.001 0.001</size>
          </box>
        </geometry>
      </visual>
    </link>
    <joint name='egp64_finger_left_joint' type='prismatic'>
      <pose relative_to='link_6'>0.02147 -0.01722 0.0103 1.5708 0 1.5708</pose>
      <parent>link_6</parent>
      <child>egp64_finger_left_link</child>
      <axis>
        <xyz>-1 0 0</xyz>
        <limit>
          <lower>-0.001</lower>
          <upper>0.04</upper>
          <effort>100</effort>
          <velocity>0.2</velocity>
        </limit>
        <dynamics>
          <damping>1</damping>
          <friction>1</friction>
          <spring_reference>0</spring_reference>
          <spring_stiffness>0</spring_stiffness>
        </dynamics>
      </axis>
    </joint>
    <link name='egp64_finger_left_link'>
      <pose relative_to='egp64_finger_left_joint'>0 0 0 0 -0 0</pose>
      <inertial>
        <pose>0.03568 -0.005547 0.00062 0 -0 0</pose>
        <mass>0.003</mass>
        <inertia>
          <ixx>0.00200003</ixx>
          <ixy>-2.84394e-07</ixy>
          <ixz>-7.7562e-08</ixz>
          <iyy>0.00200261</iyy>
          <iyz>-8.4568e-09</iyz>
          <izz>0.00200264</izz>
        </inertia>
      </inertial>
      <collision name='egp64_finger_left_link_collision'>
        <pose>0 0 0 0 -0 0</pose>
        <geometry>
          <mesh>
            <scale>1 1 1</scale>
            <uri>file:///home/dushyant/Documents/IRB_Mobile/MobileRobot/install/robotbody/share/robotbody/meshes/egp64/egp64_LeftFingerBase.dae</uri>
          </mesh>
        </geometry>
      </collision>
      <collision name='egp64_finger_left_link_fixed_joint_lump__egp64_fingertip_left_link_collision_1'>
        <pose>0.03869 -0.0005 0.00093 0 -0 0</pose>
        <geometry>
          <mesh>
            <scale>1 1 1</scale>
            <uri>file:///home/dushyant/Documents/IRB_Mobile/MobileRobot/install/robotbody/share/robotbody/meshes/egp64/egp64_LeftFinger.dae</uri>
          </mesh>
        </geometry>
      </collision>
      <visual name='egp64_finger_left_link_visual'>
        <pose>0 0 0 0 -0 0</pose>
        <geometry>
          <mesh>
            <scale>1 1 1</scale>
            <uri>file:///home/dushyant/Documents/IRB_Mobile/MobileRobot/install/robotbody/share/robotbody/meshes/egp64/egp64_LeftFingerBase.dae</uri>
          </mesh>
        </geometry>
      </visual>
      <visual name='egp64_finger_left_link_fixed_joint_lump__egp64_fingertip_left_link_visual_1'>
        <pose>0.03869 -0.0005 0.00093 0 -0 0</pose>
        <geometry>
          <mesh>
            <scale>1 1 1</scale>
            <uri>file:///home/dushyant/Documents/IRB_Mobile/MobileRobot/install/robotbody/share/robotbody/meshes/egp64/egp64_LeftFinger.dae</uri>
          </mesh>
        </geometry>
      </visual>
    </link>
    <joint name='egp64_finger_right_joint' type='prismatic'>
      <pose relative_to='link_6'>0.02147 -0.04735 0.0121 1.5708 0 1.5708</pose>
      <parent>link_6</parent>
      <child>egp64_finger_right_link</child>
      <axis>
        <xyz>1 0 0</xyz>
        <limit>
          <lower>-0.001</lower>
          <upper>0.04</upper>
          <effort>100</effort>
          <velocity>0.2</velocity>
        </limit>
        <dynamics>
          <damping>1</damping>
          <friction>1</friction>
          <spring_reference>0</spring_reference>
          <spring_stiffness>0</spring_stiffness>
        </dynamics>
      </axis>
    </joint>
    <link name='egp64_finger_right_link'>
      <pose relative_to='egp64_finger_right_joint'>0 0 0 0 -0 0</pose>
      <inertial>
        <pose>-0.018273 -0.005327 0.00062 0 -0 0</pose>
        <mass>0.003</mass>
        <inertia>
          <ixx>0.00200001</ixx>
          <ixy>1.23691e-08</ixy>
          <ixz>1.10608e-08</ixz>
          <iyy>0.00200006</iyy>
          <iyz>-2.5792e-09</iyz>
          <izz>0.00200006</izz>
        </inertia>
      </inertial>
      <collision name='egp64_finger_right_link_collision'>
        <pose>0 0 0 0 -0 0</pose>
        <geometry>
          <mesh>
            <scale>1 1 1</scale>
            <uri>file:///home/dushyant/Documents/IRB_Mobile/MobileRobot/install/robotbody/share/robotbody/meshes/egp64/egp64_RightFingerBase.dae</uri>
          </mesh>
        </geometry>
      </collision>
      <collision name='egp64_finger_right_link_fixed_joint_lump__egp64_fingertip_right_link_collision_1'>
        <pose>-0.01211 -0.00197 0.00093 0 -0 0</pose>
        <geometry>
          <mesh>
            <scale>1 1 1</scale>
            <uri>file:///home/dushyant/Documents/IRB_Mobile/MobileRobot/install/robotbody/share/robotbody/meshes/egp64/egp64_RightFinger.dae</uri>
          </mesh>
        </geometry>
      </collision>
      <visual name='egp64_finger_right_link_visual'>
        <pose>0 0 0 0 -0 0</pose>
        <geometry>
          <mesh>
            <scale>1 1 1</scale>
            <uri>file:///home/dushyant/Documents/IRB_Mobile/MobileRobot/install/robotbody/share/robotbody/meshes/egp64/egp64_RightFingerBase.dae</uri>
          </mesh>
        </geometry>
      </visual>
      <visual name='egp64_finger_right_link_fixed_joint_lump__egp64_fingertip_right_link_visual_1'>
        <pose>-0.01211 -0.00197 0.00093 0 -0 0</pose>
        <geometry>
          <mesh>
            <scale>1 1 1</scale>
            <uri>file:///home/dushyant/Documents/IRB_Mobile/MobileRobot/install/robotbody/share/robotbody/meshes/egp64/egp64_RightFinger.dae</uri>
          </mesh>
        </geometry>
      </visual>
    </link>
    <joint name='drivewhl_l_joint' type='revolute'>
      <pose relative_to='mobile_base_link'>0 0.165 -0.05 0 -0 0</pose>
      <parent>mobile_base_link</parent>
      <child>drivewhl_l_link</child>
      <axis>
        <xyz>0 1 0</xyz>
        <limit>
          <lower>-1e+16</lower>
          <upper>1e+16</upper>
        </limit>
        <dynamics>
          <spring_reference>0</spring_reference>
          <spring_stiffness>0</spring_stiffness>
        </dynamics>
      </axis>
    </joint>
    <link name='drivewhl_l_link'>
      <pose relative_to='drivewhl_l_joint'>0 0 0 0 -0 0</pose>
      <inertial>
        <pose>0 0 0 1.5708 -0 0</pose>
        <mass>1</mass>
        <inertia>
          <ixx>0.0013</ixx>
          <ixy>0</ixy>
          <ixz>0</ixz>
          <iyy>0.0013</iyy>
          <iyz>0</iyz>
          <izz>0.00245</izz>
        </inertia>
      </inertial>
      <collision name='drivewhl_l_link_collision'>
        <pose>0 0 0 1.5708 -0 0</pose>
        <geometry>
          <cylinder>
            <length>0.03</length>
            <radius>0.07</radius>
          </cylinder>
        </geometry>
        <surface>
          <contact>
            <ode>
              <kp>1e+07</kp>
              <kd>1</kd>
            </ode>
          </contact>
          <friction>
            <ode>
              <mu>1</mu>
              <mu2>1</mu2>
            </ode>
          </friction>
        </surface>
      </collision>
      <visual name='drivewhl_l_link_visual'>
        <pose>0 0 0 1.5708 -0 0</pose>
        <geometry>
          <cylinder>
            <length>0.03</length>
            <radius>0.07</radius>
          </cylinder>
        </geometry>
      </visual>
    </link>
    <joint name='drivewhl_r_joint' type='revolute'>
      <pose relative_to='mobile_base_link'>0 -0.165 -0.05 0 -0 0</pose>
      <parent>mobile_base_link</parent>
      <child>drivewhl_r_link</child>
      <axis>
        <xyz>0 1 0</xyz>
        <limit>
          <lower>-1e+16</lower>
          <upper>1e+16</upper>
        </limit>
        <dynamics>
          <spring_reference>0</spring_reference>
          <spring_stiffness>0</spring_stiffness>
        </dynamics>
      </axis>
    </joint>
    <link name='drivewhl_r_link'>
      <pose relative_to='drivewhl_r_joint'>0 0 0 0 -0 0</pose>
      <inertial>
        <pose>0 0 0 1.5708 -0 0</pose>
        <mass>1</mass>
        <inertia>
          <ixx>0.0013</ixx>
          <ixy>0</ixy>
          <ixz>0</ixz>
          <iyy>0.0013</iyy>
          <iyz>0</iyz>
          <izz>0.00245</izz>
        </inertia>
      </inertial>
      <collision name='drivewhl_r_link_collision'>
        <pose>0 0 0 1.5708 -0 0</pose>
        <geometry>
          <cylinder>
            <length>0.03</length>
            <radius>0.07</radius>
          </cylinder>
        </geometry>
        <surface>
          <contact>
            <ode>
              <kp>1e+07</kp>
              <kd>1</kd>
            </ode>
          </contact>
          <friction>
            <ode>
              <mu>1</mu>
              <mu2>1</mu2>
            </ode>
          </friction>
        </surface>
      </collision>
      <visual name='drivewhl_r_link_visual'>
        <pose>0 0 0 1.5708 -0 0</pose>
        <geometry>
          <cylinder>
            <length>0.03</length>
            <radius>0.07</radius>
          </cylinder>
        </geometry>
      </visual>
    </link>
    <plugin name='two_wheeled_robot_diff_drive' filename='libgazebo_ros_diff_drive.so'>
      <update_rate>60</update_rate>
      <left_joint>drivewhl_l_joint</left_joint>
      <right_joint>drivewhl_r_joint</right_joint>
      <wheel_separation>0.33</wheel_separation>
      <wheel_diameter>0.14</wheel_diameter>
      <max_wheel_torque>20</max_wheel_torque>
      <command_topic>cmd_vel</command_topic>
      <publish_odom>1</publish_odom>
      <publish_odom_tf>1</publish_odom_tf>
      <publish_wheel_tf>0</publish_wheel_tf>
      <odometry_topic>odom</odometry_topic>
      <odometry_frame>odom</odometry_frame>
      <robot_base_frame>mobile_base_link</robot_base_frame>
      <odometry_source>1</odometry_source>
      <ros>
        <remapping>odom:=wheel/odometry</remapping>
      </ros>
    </plugin>
    <static>0</static>
    <plugin name='gazebo_ros2_control' filename='libgazebo_ros2_control.so'>
      <parameters>/home/dushyant/Documents/IRB_Mobile/MobileRobot/install/robotbody/share/robotbody/config/irb120egp64_controller.yaml</parameters>
    </plugin>
  </model>
</sdf>