<?xml version="1.0" ?>
<!-- =================================================================================== -->
<!-- |    This document was autogenerated by xacro from mobile_manipulator.urdf.xacro  | -->
<!-- |    EDITING THIS FILE BY HAND IS NOT RECOMMENDED                                 | -->
<!-- =================================================================================== -->
<robot name="mobile_manipulator">
  <!-- ********************** ROBOT BASE *********************************  -->
  <link name="mobile_base_link">
    <visual>
      <origin rpy="0 0 0" xyz="0 0 0.0"/>
      <geometry>
        <box size="0.3 0.3 0.1"/>
      </geometry>
      <material name="Red">
        <color rgba="1.0 0.0 0.0 1.0"/>
      </material>
    </visual>
    <collision>
      <geometry>
        <box size="0.3 0.3 0.1"/>
      </geometry>
    </collision>
    <inertial>
      <origin rpy="1.5707963267948966 0 1.5707963267948966" xyz="0 0 0"/>
      <mass value="10.0"/>
      <inertia ixx="0.08333333333333334" ixy="0.0" ixz="0.0" iyy="0.15" iyz="0.0" izz="0.08333333333333334"/>
    </inertial>
  </link>
  <gazebo reference="mobile_base_link">
    <material>Gazebo/Pioneer2Body</material>
  </gazebo>
  <!-- ****************** ROBOT BASE FOOTPRINT ***************************  -->
  <!-- Define the center of the main robot chassis projected on the ground -->
  <link name="base_footprint">
    <!--<xacro:box_inertia m="0" w="0" d="0" h="0"/> -->
  </link>
  <!-- The base footprint of the robot is located underneath the chassis -->
  <joint name="base_joint" type="fixed">
    <parent link="mobile_base_link"/>
    <child link="base_footprint"/>
    <origin rpy="0 0 0" xyz="0.0 0.0 -0.12000000000000001"/>
  </joint>
  <link name="drivewhl_l_link">
    <visual>
      <origin rpy="1.5707963267948966 0 0" xyz="0 0 0"/>
      <geometry>
        <cylinder length="0.03" radius="0.07"/>
      </geometry>
      <material name="Gray">
        <color rgba="0.5 0.5 0.5 1.0"/>
      </material>
    </visual>
    <collision>
      <origin rpy="1.5707963267948966 0 0" xyz="0 0 0"/>
      <geometry>
        <cylinder length="0.03" radius="0.07"/>
      </geometry>
    </collision>
    <inertial>
      <origin rpy="1.5707963267948966 0 0" xyz="0 0 0"/>
      <mass value="1.0"/>
      <inertia ixx="0.0013000000000000002" ixy="0" ixz="0" iyy="0.0013000000000000002" iyz="0" izz="0.0024500000000000004"/>
    </inertial>
  </link>
  <!-- Connect the wheels to the base_link at the appropriate location, and 
         define a continuous joint to allow the wheels to freely rotate about
         an axis -->
  <joint name="drivewhl_l_joint" type="continuous">
    <parent link="mobile_base_link"/>
    <child link="drivewhl_l_link"/>
    <origin rpy="0 0 0" xyz="-0.0 0.16499999999999998 -0.05"/>
    <axis xyz="0 1 0"/>
  </joint>
  <gazebo reference="drivewhl_l_link">
    <mu1 value="1.0"/>
    <mu2 value="1.0"/>
    <kp value="10000000.0"/>
    <kd value="1.0"/>
  </gazebo>
  <link name="drivewhl_r_link">
    <visual>
      <origin rpy="1.5707963267948966 0 0" xyz="0 0 0"/>
      <geometry>
        <cylinder length="0.03" radius="0.07"/>
      </geometry>
      <material name="Gray">
        <color rgba="0.5 0.5 0.5 1.0"/>
      </material>
    </visual>
    <collision>
      <origin rpy="1.5707963267948966 0 0" xyz="0 0 0"/>
      <geometry>
        <cylinder length="0.03" radius="0.07"/>
      </geometry>
    </collision>
    <inertial>
      <origin rpy="1.5707963267948966 0 0" xyz="0 0 0"/>
      <mass value="1.0"/>
      <inertia ixx="0.0013000000000000002" ixy="0" ixz="0" iyy="0.0013000000000000002" iyz="0" izz="0.0024500000000000004"/>
    </inertial>
  </link>
  <!-- Connect the wheels to the base_link at the appropriate location, and 
         define a continuous joint to allow the wheels to freely rotate about
         an axis -->
  <joint name="drivewhl_r_joint" type="continuous">
    <parent link="mobile_base_link"/>
    <child link="drivewhl_r_link"/>
    <origin rpy="0 0 0" xyz="-0.0 -0.16499999999999998 -0.05"/>
    <axis xyz="0 1 0"/>
  </joint>
  <gazebo reference="drivewhl_r_link">
    <mu1 value="1.0"/>
    <mu2 value="1.0"/>
    <kp value="10000000.0"/>
    <kd value="1.0"/>
  </gazebo>
  <!-- *********************** CASTER WHEEL ******************************  -->
  <!-- We add a caster wheel. It will be modeled as sphere.
       We define the wheel’s geometry, material and the joint to connect it to 
       base_link at the appropriate location. -->
  <link name="front_caster">
    <!--
    <visual>
      <geometry>
        <sphere radius="${(wheel_radius+wheel_zoff-(base_height/2))}"/>
      </geometry>
      <material name="Cyan">
        <color rgba="0 1.0 1.0 1.0"/>
      </material>
    </visual>
    -->
    <collision>
      <origin rpy="0 0 0" xyz="0 0 0"/>
      <geometry>
        <sphere radius="0.07"/>
      </geometry>
    </collision>
    <inertial>
      <mass value="0.3"/>
      <inertia ixx="0.0005880000000000001" ixy="0.0" ixz="0.0" iyy="0.0005880000000000001" iyz="0.0" izz="0.0005880000000000001"/>
    </inertial>
  </link>
  <gazebo reference="front_caster">
    <mu1>0.01</mu1>
    <mu2>0.01</mu2>
    <kp value="10000000.0"/>
    <kd value="1.0"/>
    <material>Gazebo/White</material>
  </gazebo>
  <joint name="caster_front_joint" type="fixed">
    <parent link="mobile_base_link"/>
    <child link="front_caster"/>
    <origin rpy="0 0 0" xyz="0.15 0.0 -0.05"/>
    <dynamics damping="0.01" friction="0.0"/>
  </joint>
  <link name="back_caster">
    <!--
    <visual>
      <geometry>
        <sphere radius="${(wheel_radius+wheel_zoff-(base_height/2))}"/>
      </geometry>
      <material name="Cyan">
        <color rgba="0 1.0 1.0 1.0"/>
      </material>
    </visual>
    -->
    <collision>
      <origin rpy="0 0 0" xyz="0 0 0"/>
      <geometry>
        <sphere radius="0.07"/>
      </geometry>
    </collision>
    <inertial>
      <mass value="0.3"/>
      <inertia ixx="0.0005880000000000001" ixy="0.0" ixz="0.0" iyy="0.0005880000000000001" iyz="0.0" izz="0.0005880000000000001"/>
    </inertial>
  </link>
  <gazebo reference="back_caster">
    <mu1>0.01</mu1>
    <mu2>0.01</mu2>
    <kp value="10000000.0"/>
    <kd value="1.0"/>
    <material>Gazebo/White</material>
  </gazebo>
  <joint name="caster_back_joint" type="fixed">
    <parent link="mobile_base_link"/>
    <child link="back_caster"/>
    <origin rpy="0 0 0" xyz="-0.15 0.0 -0.05"/>
    <dynamics damping="0.01" friction="0.0"/>
  </joint>
  <!-- *********************** WHEEL ODOMETRY ***************************    -->
  <gazebo>
    <plugin filename="libgazebo_ros_diff_drive.so" name="two_wheeled_robot_diff_drive">
      <update_rate>60</update_rate>
      <left_joint>drivewhl_l_joint</left_joint>
      <right_joint>drivewhl_r_joint</right_joint>
      <wheel_separation>0.33</wheel_separation>
      <wheel_diameter>0.14</wheel_diameter>
      <max_wheel_torque>20</max_wheel_torque>
      <!--<max_wheel_acceleration>3.0</max_wheel_acceleration>  -->
      <command_topic>cmd_vel</command_topic>
      <publish_odom>true</publish_odom>
      <publish_odom_tf>true</publish_odom_tf>
      <publish_wheel_tf>false</publish_wheel_tf>
      <odometry_topic>odom</odometry_topic>
      <odometry_frame>odom</odometry_frame>
      <robot_base_frame>mobile_base_link</robot_base_frame>
      <odometry_source>1</odometry_source>
      <ros>
        <remapping>odom:=wheel/odometry</remapping>
      </ros>
    </plugin>
  </gazebo>
  <!-- ===== ARGUMENTS ===== -->
  <!-- Conversion were obtained from http://www.e-paint.co.uk/Lab_values.asp
       unless otherwise stated. -->
  <ros2_control name="ArmControl" type="system">
    <hardware>
      <plugin>gazebo_ros2_control/GazeboSystem</plugin>
    </hardware>
    <joint name="irb120_joint1">
      <command_interface name="position"/>
      <command_interface name="velocity"/>
      <state_interface name="position"/>
      <state_interface name="velocity"/>
      <state_interface name="effort"/>
    </joint>
    <joint name="irb120_joint2">
      <command_interface name="position"/>
      <command_interface name="velocity"/>
      <state_interface name="position"/>
      <state_interface name="velocity"/>
      <state_interface name="effort"/>
    </joint>
    <joint name="irb120_joint3">
      <command_interface name="position"/>
      <command_interface name="velocity"/>
      <state_interface name="position"/>
      <state_interface name="velocity"/>
      <state_interface name="effort"/>
    </joint>
    <joint name="irb120_joint4">
      <command_interface name="position"/>
      <command_interface name="velocity"/>
      <state_interface name="position"/>
      <state_interface name="velocity"/>
      <state_interface name="effort"/>
    </joint>
    <joint name="irb120_joint5">
      <command_interface name="position"/>
      <command_interface name="velocity"/>
      <state_interface name="position"/>
      <state_interface name="velocity"/>
      <state_interface name="effort"/>
    </joint>
    <joint name="irb120_joint6">
      <command_interface name="position"/>
      <command_interface name="velocity"/>
      <state_interface name="position"/>
      <state_interface name="velocity"/>
      <state_interface name="effort"/>
    </joint>
    <joint name="egp64_finger_left_joint">
      <command_interface name="position"/>
      <state_interface name="position"/>
      <state_interface name="velocity"/>
      <state_interface name="effort"/>
    </joint>
    <joint name="egp64_finger_right_joint">
      <command_interface name="position"/>
      <state_interface name="position"/>
      <state_interface name="velocity"/>
      <state_interface name="effort"/>
    </joint>
  </ros2_control>
  <!-- =================================== -->
  <!-- ========== END-EFFECTORS ========== -->
  <!-- === SCHUNK EGP-64 GRIPPER === -->
  <!--
    <transmission name="egp64_left_finger_trans">
      <type>transmission_interface/SimpleTransmission</type>
      <joint name="egp64_finger_left_joint">
        <hardwareInterface>hardware_interface/PositionJointInterface</hardwareInterface>
      </joint>
      <actuator name="egp64_left_finger_motor">
        <mechanicalReduction>1</mechanicalReduction>
      </actuator>
    </transmission>
    <transmission name="egp64_right_finger_trans">
      <type>transmission_interface/SimpleTransmission</type>
      <joint name="egp64_finger_right_joint">
        <hardwareInterface>hardware_interface/PositionJointInterface</hardwareInterface>
      </joint>
      <actuator name="egp64_right_finger_motor">
        <mechanicalReduction>1</mechanicalReduction>
      </actuator>
    </transmission>  
    -->
  <!-- === SCHUNK EGP-64 GRIPPER === -->
  <!-- Load ABB IRB120 ROS2_CONTROL file: -->
  <gazebo>
    <plugin filename="libgazebo_ros2_control.so" name="gazebo_ros2_control">
      <parameters>/home/dushyant/Documents/IRB_Mobile/MobileRobot/install/robotbody/share/robotbody/config/irb120egp64_controller.yaml</parameters>
    </plugin>
  </gazebo>
  <!-- ***** ABB-IRB120 ROBOT .urdf SERIAL CHAIN ***** -->
  <!-- Link list: -->
  <!-- base_link -->
  <link name="base_link">
    <inertial>
      <mass value="6.215"/>
      <origin rpy="0 0 0" xyz="-0.04204 8.01E-05 0.07964"/>
      <inertia ixx="0.0247272" ixy="-8.0784E-05" ixz="0.00130902" iyy="0.0491285" iyz="-8.0419E-06" izz="0.0472376"/>
    </inertial>
    <visual>
      <origin rpy="0 0 0" xyz="0 0 0"/>
      <geometry>
        <mesh filename="file:///home/dushyant/Documents/IRB_Mobile/MobileRobot/install/robotbody/share/robotbody/meshes/visual/base_link.dae"/>
      </geometry>
      <material name="">
        <color rgba="0.7372549 0.3490196 0.1607843 1"/>
      </material>
    </visual>
    <collision>
      <origin rpy="0 0 0" xyz="0 0 0"/>
      <geometry>
        <mesh filename="file:///home/dushyant/Documents/IRB_Mobile/MobileRobot/install/robotbody/share/robotbody/meshes/collision/base_link.stl"/>
      </geometry>
      <material name="">
        <color rgba="1 1 0 1"/>
      </material>
    </collision>
  </link>
  <!-- link_1 -->
  <link name="link_1">
    <visual>
      <origin rpy="0 0 0" xyz="0 0 0"/>
      <geometry>
        <mesh filename="file:///home/dushyant/Documents/IRB_Mobile/MobileRobot/install/robotbody/share/robotbody/meshes/visual/link_1.dae"/>
      </geometry>
      <material name="">
        <color rgba="0.7372549 0.3490196 0.1607843 1"/>
      </material>
    </visual>
    <collision>
      <origin rpy="0 0 0" xyz="0 0 0"/>
      <geometry>
        <mesh filename="file:///home/dushyant/Documents/IRB_Mobile/MobileRobot/install/robotbody/share/robotbody/meshes/collision/link_1.stl"/>
      </geometry>
      <material name="">
        <color rgba="1 1 0 1"/>
      </material>
    </collision>
  </link>
  <!-- link_2 -->
  <link name="link_2">
    <visual>
      <origin rpy="0 0 0" xyz="0 0 0"/>
      <geometry>
        <mesh filename="file:///home/dushyant/Documents/IRB_Mobile/MobileRobot/install/robotbody/share/robotbody/meshes/visual/link_2.dae"/>
      </geometry>
      <material name="">
        <color rgba="0.7372549 0.3490196 0.1607843 1"/>
      </material>
    </visual>
    <collision>
      <origin rpy="0 0 0" xyz="0 0 0"/>
      <geometry>
        <mesh filename="file:///home/dushyant/Documents/IRB_Mobile/MobileRobot/install/robotbody/share/robotbody/meshes/collision/link_2.stl"/>
      </geometry>
      <material name="">
        <color rgba="1 1 0 1"/>
      </material>
    </collision>
  </link>
  <!-- link_3 -->
  <link name="link_3">
    <visual>
      <origin rpy="0 0 0" xyz="0 0 0"/>
      <geometry>
        <mesh filename="file:///home/dushyant/Documents/IRB_Mobile/MobileRobot/install/robotbody/share/robotbody/meshes/visual/link_3.dae"/>
      </geometry>
      <material name="">
        <color rgba="0.7372549 0.3490196 0.1607843 1"/>
      </material>
    </visual>
    <collision>
      <origin rpy="0 0 0" xyz="0 0 0"/>
      <geometry>
        <mesh filename="file:///home/dushyant/Documents/IRB_Mobile/MobileRobot/install/robotbody/share/robotbody/meshes/collision/link_3.stl"/>
      </geometry>
      <material name="">
        <color rgba="1 1 0 1"/>
      </material>
    </collision>
  </link>
  <!-- link_4 -->
  <link name="link_4">
    <visual>
      <origin rpy="0 0 0" xyz="0 0 0"/>
      <geometry>
        <mesh filename="file:///home/dushyant/Documents/IRB_Mobile/MobileRobot/install/robotbody/share/robotbody/meshes/visual/link_4.dae"/>
      </geometry>
      <material name="">
        <color rgba="0.7372549 0.3490196 0.1607843 1"/>
      </material>
    </visual>
    <collision>
      <origin rpy="0 0 0" xyz="0 0 0"/>
      <geometry>
        <mesh filename="file:///home/dushyant/Documents/IRB_Mobile/MobileRobot/install/robotbody/share/robotbody/meshes/collision/link_4.stl"/>
      </geometry>
      <material name="">
        <color rgba="1 1 0 1"/>
      </material>
    </collision>
  </link>
  <!-- link_5 -->
  <link name="link_5">
    <visual>
      <origin rpy="0 0 0" xyz="0 0 0"/>
      <geometry>
        <mesh filename="file:///home/dushyant/Documents/IRB_Mobile/MobileRobot/install/robotbody/share/robotbody/meshes/visual/link_5.dae"/>
      </geometry>
      <material name="">
        <color rgba="0.7372549 0.3490196 0.1607843 1"/>
      </material>
    </visual>
    <collision>
      <origin rpy="0 0 0" xyz="0 0 0"/>
      <geometry>
        <mesh filename="file:///home/dushyant/Documents/IRB_Mobile/MobileRobot/install/robotbody/share/robotbody/meshes/collision/link_5.stl"/>
      </geometry>
      <material name="">
        <color rgba="1 1 0 1"/>
      </material>
    </collision>
  </link>
  <!-- link_6 -->
  <link name="link_6">
    <visual>
      <origin rpy="0 0 0" xyz="0 0 0"/>
      <geometry>
        <mesh filename="file:///home/dushyant/Documents/IRB_Mobile/MobileRobot/install/robotbody/share/robotbody/meshes/visual/link_6.dae"/>
      </geometry>
      <material name="">
        <color rgba="0.1882353 0.1960784 0.2039216 1"/>
      </material>
    </visual>
    <collision>
      <origin rpy="0 0 0" xyz="0 0 0"/>
      <geometry>
        <mesh filename="file:///home/dushyant/Documents/IRB_Mobile/MobileRobot/install/robotbody/share/robotbody/meshes/collision/link_6.stl"/>
      </geometry>
      <material name="">
        <color rgba="1 1 0 1"/>
      </material>
    </collision>
  </link>
  <!-- end of link list -->
  <!-- Joint list: -->
  <!-- joint_1 -->
  <joint name="irb120_joint1" type="revolute">
    <origin rpy="0 0 0" xyz="0 0 0"/>
    <parent link="base_link"/>
    <child link="link_1"/>
    <limit effort="0" lower="-2.87979" upper="2.87979" velocity="4.36332"/>
    <axis xyz="0 0 1"/>
    <dynamics damping="50.0" friction="1.0"/>
  </joint>
  <!-- joint_2 -->
  <joint name="irb120_joint2" type="revolute">
    <origin rpy="0 0 0" xyz="0 0 0.29"/>
    <parent link="link_1"/>
    <child link="link_2"/>
    <limit effort="0" lower="-1.91986" upper="1.91986" velocity="4.36332"/>
    <axis xyz="0 1 0"/>
    <dynamics damping="50.0" friction="1.0"/>
  </joint>
  <!-- joint_3 -->
  <joint name="irb120_joint3" type="revolute">
    <origin rpy="0 0 0" xyz="0 0 0.27"/>
    <parent link="link_2"/>
    <child link="link_3"/>
    <limit effort="0" lower="-1.91986" upper="1.22173" velocity="4.36332"/>
    <axis xyz="0 1 0"/>
    <dynamics damping="10.0" friction="1.0"/>
  </joint>
  <!-- joint_4 -->
  <joint name="irb120_joint4" type="revolute">
    <origin rpy="0 0 0" xyz="0 0 0.07"/>
    <parent link="link_3"/>
    <child link="link_4"/>
    <limit effort="0" lower="-2.79253" upper="2.79253" velocity="5.58505"/>
    <axis xyz="1 0 0"/>
    <dynamics damping="5.0" friction="1.0"/>
  </joint>
  <!-- joint_5 -->
  <joint name="irb120_joint5" type="revolute">
    <origin rpy="0 0 0" xyz="0.302 0 0"/>
    <parent link="link_4"/>
    <child link="link_5"/>
    <limit effort="0" lower="-2.094395" upper="2.094395" velocity="5.58505"/>
    <axis xyz="0 1 0"/>
    <dynamics damping="2.0" friction="1.0"/>
  </joint>
  <!-- joint_6 -->
  <joint name="irb120_joint6" type="revolute">
    <origin rpy="0 0 0" xyz="0.072 0 0"/>
    <parent link="link_5"/>
    <child link="link_6"/>
    <limit effort="0" lower="-6.98132" upper="6.98132" velocity="7.33038"/>
    <axis xyz="1 0 0"/>
    <dynamics damping="1.0" friction="1.0"/>
  </joint>
  <!-- end of joint list -->
  <!-- ROS-Industrial 'base' frame: base_link to ABB World Coordinates transform -->
  <link name="base"/>
  <joint name="base_link-base" type="fixed">
    <origin rpy="0 0 0" xyz="0 0 0"/>
    <parent link="base_link"/>
    <child link="base"/>
  </joint>
  <!-- ROS-Industrial 'flange' frame: attachment point for EEF models -->
  <link name="flange"/>
  <joint name="joint_6-flange" type="fixed">
    <origin rpy="0 0 0" xyz="0 0 0"/>
    <parent link="link_6"/>
    <child link="flange"/>
  </joint>
  <!-- ROS-Industrial 'tool0' frame: all-zeros tool frame -->
  <link name="tool0"/>
  <joint name="link_6-tool0" type="fixed">
    <origin rpy="0 1.5707963267948966 0" xyz="0 0 0"/>
    <parent link="flange"/>
    <child link="tool0"/>
  </joint>
  <!-- =================================== -->
  <!-- ========== END-EFFECTORS ========== -->
  <!-- === SCHUNK EGP-64 GRIPPER === -->
  <!-- Schunk coupler (LINK): -->
  <link name="schunk_coupler">
    <visual>
      <geometry>
        <mesh filename="file:///home/dushyant/Documents/IRB_Mobile/MobileRobot/install/robotbody/share/robotbody/meshes/egp64/egp64_Adapter.dae"/>
      </geometry>
    </visual>
    <collision>
      <geometry>
        <mesh filename="file:///home/dushyant/Documents/IRB_Mobile/MobileRobot/install/robotbody/share/robotbody/meshes/egp64/egp64_Adapter.dae"/>
      </geometry>
    </collision>
    <inertial>
      <!--<origin xyz="0 0 0" rpy="0 0 ${pi/4}" />-->
      <origin rpy="0 0 1.5707963267948966" xyz="0 0 0"/>
      <mass value="0.001"/>
      <inertia ixx="0.001" ixy="0.0" ixz="0.0" iyy="0.001" iyz="0.0" izz="0.001"/>
    </inertial>
  </link>
  <!-- Schunk coupler (JOINT): -->
  <joint name="schunk_coupler_joint" type="fixed">
    <!--<origin xyz="0 0 0.001" rpy="0 0 ${pi/4}" />-->
    <origin rpy="0 0 1.5707963267948966" xyz="0 0 0.001"/>
    <parent link="tool0"/>
    <child link="schunk_coupler"/>
  </joint>
  <gazebo reference="schunk_coupler">
    <mu1>0.9</mu1>
    <mu2>0.9</mu2>
    <material>Gazebo/Black</material>
  </gazebo>
  <link name="egp64_gripper_base_link">
    <inertial>
      <origin rpy="0 0 0" xyz="0 0 0"/>
      <mass value="0.005"/>
      <inertia ixx="0.001" ixy="0.0" ixz="0.0" iyy="0.001" iyz="0.0" izz="0.001"/>
    </inertial>
    <visual>
      <geometry>
        <mesh filename="file:///home/dushyant/Documents/IRB_Mobile/MobileRobot/install/robotbody/share/robotbody/meshes/egp64/egp64_BaseNoAdapter.dae"/>
      </geometry>
      <material name="blue">
        <color rgba="0 0 1 1"/>
      </material>
    </visual>
    <collision>
      <geometry>
        <mesh filename="file:///home/dushyant/Documents/IRB_Mobile/MobileRobot/install/robotbody/share/robotbody/meshes/egp64/egp64_BaseNoAdapter.dae"/>
      </geometry>
      <material name="blue"/>
    </collision>
  </link>
  <joint name="egp64_coupler" type="fixed">
    <parent link="schunk_coupler"/>
    <child link="egp64_gripper_base_link"/>
    <origin rpy="0 0 0" xyz="-0.03205 0.01812 0.02047"/>
  </joint>
  <!-- LEFT FINGER BASE -->
  <link name="egp64_finger_left_link">
    <inertial>
      <origin rpy="0 0 0" xyz="0.01483 -0.00782 0"/>
      <mass value="0.002"/>
      <inertia ixx="0.001" ixy="0.0" ixz="0.0" iyy="0.001" iyz="0.0" izz="0.001"/>
    </inertial>
    <visual>
      <geometry>
        <mesh filename="file:///home/dushyant/Documents/IRB_Mobile/MobileRobot/install/robotbody/share/robotbody/meshes/egp64/egp64_LeftFingerBase.dae"/>
      </geometry>
      <material name="black">
        <color rgba="0 0 0 1"/>
      </material>
    </visual>
    <collision>
      <geometry>
        <mesh filename="file:///home/dushyant/Documents/IRB_Mobile/MobileRobot/install/robotbody/share/robotbody/meshes/egp64/egp64_LeftFingerBase.dae"/>
      </geometry>
      <material name="black"/>
    </collision>
  </link>
  <joint name="egp64_finger_left_joint" type="prismatic">
    <parent link="egp64_gripper_base_link"/>
    <child link="egp64_finger_left_link"/>
    <limit effort="100" lower="-0.001" upper="0.04" velocity="0.2"/>
    <origin rpy="0 0 0" xyz="0.01483 -0.00782 0"/>
    <axis xyz="-1 0 0"/>
    <dynamics damping="1.0" friction="1.0"/>
  </joint>
  <!-- LEFT FINGERTIP -->
  <link name="egp64_fingertip_left_link">
    <inertial>
      <origin rpy="0 0 0" xyz="0.03869 -0.0005 0.00093"/>
      <mass value="0.001"/>
      <inertia ixx="0.001" ixy="0.0" ixz="0.0" iyy="0.001" iyz="0.0" izz="0.001"/>
    </inertial>
    <visual>
      <geometry>
        <mesh filename="file:///home/dushyant/Documents/IRB_Mobile/MobileRobot/install/robotbody/share/robotbody/meshes/egp64/egp64_LeftFinger.dae"/>
      </geometry>
      <material name="silver">
        <color rgba="0.8 0.8 0.8 1"/>
      </material>
    </visual>
    <collision>
      <geometry>
        <mesh filename="file:///home/dushyant/Documents/IRB_Mobile/MobileRobot/install/robotbody/share/robotbody/meshes/egp64/egp64_LeftFinger.dae"/>
      </geometry>
      <material name="black"/>
    </collision>
  </link>
  <joint name="egp64_fingertip_left_joint" type="fixed">
    <parent link="egp64_finger_left_link"/>
    <child link="egp64_fingertip_left_link"/>
    <origin rpy="0 0 0" xyz="0.03869 -0.0005 0.00093"/>
  </joint>
  <!-- RIGHT FINGER BASE -->
  <link name="egp64_finger_right_link">
    <inertial>
      <origin rpy="0 0 0" xyz="-0.0153 -0.00602 0"/>
      <mass value="0.002"/>
      <inertia ixx="0.001" ixy="0.0" ixz="0.0" iyy="0.001" iyz="0.0" izz="0.001"/>
    </inertial>
    <visual>
      <geometry>
        <mesh filename="file:///home/dushyant/Documents/IRB_Mobile/MobileRobot/install/robotbody/share/robotbody/meshes/egp64/egp64_RightFingerBase.dae"/>
      </geometry>
      <material name="black"/>
    </visual>
    <collision>
      <geometry>
        <mesh filename="file:///home/dushyant/Documents/IRB_Mobile/MobileRobot/install/robotbody/share/robotbody/meshes/egp64/egp64_RightFingerBase.dae"/>
      </geometry>
      <material name="black"/>
    </collision>
  </link>
  <joint name="egp64_finger_right_joint" type="prismatic">
    <parent link="egp64_gripper_base_link"/>
    <child link="egp64_finger_right_link"/>
    <limit effort="100" lower="-0.001" upper="0.04" velocity="0.2"/>
    <origin rpy="0 0 0" xyz="-0.0153 -0.00602 0"/>
    <axis xyz="1 0 0"/>
    <dynamics damping="1.0" friction="1.0"/>
  </joint>
  <!-- RIGHT FINGERTIP -->
  <link name="egp64_fingertip_right_link">
    <inertial>
      <origin rpy="0 0 0" xyz="-0.01211 -0.00197 0.00093"/>
      <mass value="0.001"/>
      <inertia ixx="0.001" ixy="0.0" ixz="0.0" iyy="0.001" iyz="0.0" izz="0.001"/>
    </inertial>
    <visual>
      <geometry>
        <mesh filename="file:///home/dushyant/Documents/IRB_Mobile/MobileRobot/install/robotbody/share/robotbody/meshes/egp64/egp64_RightFinger.dae"/>
      </geometry>
      <material name="silver"/>
    </visual>
    <collision>
      <geometry>
        <mesh filename="file:///home/dushyant/Documents/IRB_Mobile/MobileRobot/install/robotbody/share/robotbody/meshes/egp64/egp64_RightFinger.dae"/>
      </geometry>
      <material name="black"/>
    </collision>
  </link>
  <joint name="egp64_fingertip_right_joint" type="fixed">
    <parent link="egp64_finger_right_link"/>
    <child link="egp64_fingertip_right_link"/>
    <origin rpy="0 0 0" xyz="-0.01211 -0.00197 0.00093"/>
  </joint>
  <!-- SMALL CUBE FOR GRIPPER PLUGIN -->
  <link name="EE_egp64">
    <inertial>
      <origin rpy="0 0 0" xyz="0 0 0"/>
      <mass value="0.00001"/>
      <inertia ixx="0.001" ixy="0.0" ixz="0.0" iyy="0.001" iyz="0.0" izz="0.001"/>
    </inertial>
    <visual>
      <geometry>
        <box size="0.001 0.001 0.001"/>
      </geometry>
    </visual>
  </link>
  <joint name="EE_egp64_joint" type="prismatic">
    <parent link="egp64_gripper_base_link"/>
    <child link="EE_egp64"/>
    <limit effort="10000" lower="0.0" upper="0.0" velocity="0.0"/>
    <axis xyz="1 0 0"/>
    <origin rpy="0 0 0" xyz="0.033 -0.018 0.15"/>
    <dynamics damping="1.0" friction="1.0"/>
  </joint>
  <!-- === SCHUNK EGP-64 GRIPPER === -->
  <link name="box_link">
    <visual>
      <origin rpy="0 0 0" xyz="0 0 0"/>
      <geometry>
        <box size="0.3 0.3 0.30"/>
      </geometry>
      <material name="blue">
        <color rgba="0 0 0.0 1"/>
      </material>
    </visual>
    <collision>
      <origin rpy="0 0 0" xyz="0 0 0"/>
      <geometry>
        <box size="0.3 0.3 0.30"/>
      </geometry>
    </collision>
    <!--
    <inertial>
      <origin xyz="0 0 0" rpy="0 0 0"/>
      <mass value="100"/>
      <inertia ixx="100" ixy="100" ixz="100" iyy="100" iyz="100" izz="1000000"/>
    </inertial>
    -->
  </link>
  <gazebo reference="box_link">
    <material>Gazebo/Pioneer2Body</material>
  </gazebo>
  <joint name="box_joint" type="fixed">
    <parent link="mobile_base_link"/>
    <child link="box_link"/>
    <origin rpy="0 0 0" xyz="0 0 0.2"/>
  </joint>
  <!-- Connect Arm to Base -->
  <joint name="box_arm" type="fixed">
    <parent link="box_link"/>
    <child link="base_link"/>
    <origin rpy="0 0 1.5707963267948966" xyz="0.0 0.0 0.15"/>
  </joint>
</robot>
